Workbook

Sheet INDEX
A1: NOME | B1: FUNÇÃO
A2: Abraim Oliveira Silva | B2: MARCENARIA
A3: Adriano Silva De Araujo | B3: MARCENARIA
A4: Alonso Lucas Trindade | B4: MARCENARIA
A5: Andre Nzalantima | B5: MARCENARIA
A6: Bruno da Silva Cordeiro | B6: MARCENARIA
A7: Everton De Jesus Marinho Santos | B7: MARCENARIA
A8: Gabriel Nascimento Menezes | B8: MARCENARIA
A9: Iago Dias Temoteo | B9: MARCENARIA
A10: José Renato Albuquerque de Sousa | B10: MARCENARIA
A11: Matheus da Silva Cordeiro | B11: MARCENARIA
A12: Maxmiliano Olidio da Silva | B12: MARCENARIA
... A24: Vinicius da Silva | B24: MONTAGEM

Sheet Forms
A1: Id | B1: Hora de início | C1: Hora de conclusão | D1: Email | E1: Nome | F1: Seu nome | G1: Evento que está avaliando, cidade e data | H1: Selecione a área que você faz parte | I1: Perda de material/estrutura | J1: Comentários ou Justificativa | K1: Logística Reversa | L1: Comentários ou Justificativa1 | M1: Qualidade da Entrega | N1: Comentários ou Justificativa2 | O1: Qualidade da Entrega (2) | P1: Comentários ou Justificativa3 | Q1: Prazo de entrega | R1: Comentários ou Justificativa4 | S1: Todos os equipamentos e ferramentas retornaram? | T1: Comentários ou Justificativa5 | U1: Carga na saída do galpão | V1: Comentários ou Justificativa6 | W1: Todos usaram EPI na arena? | X1: Comentários ou Justificativa7 | Y1: Estaiamento e Aterramento foram feitos de maneira correta? | Z1: Comentários ou Justificativa8 | AA1: Conduta e comportamento foram adequados? | AB1: Comentários ou Justificativa9 | AC1: Alguém faltou ou atrasou por mais de 30 minutos? Especifique. | AD1: Algum profissional teve um desempenho fora da curva, se destacando dos demais pela eficiência ou proatividade? | AE1: Conte quem se destacou e o que foi feito. | AF1: Classifique o nível do desempenho dessa pessoa
A2: 9 | B2: 46197.498 | C2: 46197.499 | D2: anônima | F2: Giovanni Bertoni | G2: Urban Walk | H2: Ferramentas e Case (Cenografia) | S2: Sim | T2: as cases retornaram em ordem
A3: 10 | B3: 46197.499 | C3: 46197.5 | D3: anônima | F3: Giovanni Bertoni | G3: Urban Walk | H3: Ferramentas e Case (Cenografia) | S3: Sim | T3: as cases retornaram em ordem
A4: 11 | B4: 46197.501 | C4: 46197.501 | D4: anônima | F4: Giovanni Bertoni | G4: Copa Sabesp | H4: Ferramentas e Case (Cenografia) | S4: Sim | T4: as cases retornaram em ordem
A5: 12 | B5: 46197.502 | C5: 46197.503 | D5: anônima | F5: Giovanni Bertoni | G5: Blue Run Piracicaba | H5: Ferramentas e Case (Cenografia) | S5: Sim | T5: cases retornaram em ordem
A6: 13 | B6: 46197.504 | C6: 46197.504 | D6: anônima | F6: Giovanni Bertoni | G6: Eco Run SP | H6: Ferramentas e Case (Cenografia) | S6: Sim | T6: todas as cases retornaram em ordem
A7: 14 | B7: 46197.504 | C7: 46197.505 | D7: anônima | F7: Giovanni Bertoni | G7: Desafio Petrobrás - Corrida RJ | H7: Ferramentas e Case (Cenografia) | S7: Sim | T7: cases retornaram em ordem
A8: 15 | B8: 46197.505 | C8: 46197.505 | D8: anônima | F8: Giovanni Bertoni | G8: Corrida Vale Vitória | H8: Ferramentas e Case (Cenografia) | S8: Sim | T8: cases retornaram em ordem
A9: 16 | B9: 46197.51 | C9: 46197.511 | D9: anônima | F9: Giovanni Bertoni | G9: Maratona de Floripa | H9: Ferramentas e Case (Cenografia) | S9: Sim | T9: cases retornaram em ordem
A10: 17 | B10: 46197.511 | C10: 46197.511 | D10: anônima | F10: Giovanni Bertoni | G10: Girl Power BH | H10: Ferramentas e Case (Cenografia) | S10: Sim | T10: cases retornaram em ordem
A11: 18 | B11: 46197.512 | C11: 46197.513 | D11: anônima | F11: Giovanni Bertoni | G11: circuito srun sorocaba | H11: Ferramentas e Case (Cenografia) | S11: Sim | T11: as cases retornaram em ordem
A12: 19 | B12: 46197.628 | C12: 46197.628 | D12: anônima | F12: Lucas vicenzo da Silva Proença | G12: NIGHT RUN - ETAPA 1 - MARINGÁ - 21/06 | H12: Produção | Q12: 10 | R12: Entregaram tudo muito bem. Sem problemas.
A13: 20 | B13: 46197.629 | C13: 46197.629 | D13: anônima | F13: Agatha | G13: NIGHT RUN - ETAPA 1 - MARINGÁ - 21/06 | H13: Atendimento | M13: 10 | N13: Elogiado pelo cliente
A14: 21 | B14: 46197.629 | C14: 46197.629 | D14: anônima | F14: Agatha | G14: CIRCUITO DE CORRIDAS VALE - SÃO LUÍS - 21/06 | H14: Atendimento | M14: 10 | N14: Elogiado pelo cliente
A15: 22 | B15: 46197.629 | C15: 46197.629 | D15: anônima | F15: Leonardo Almeida | G15: SÓ QUERO PEDALAR - RECIFE - 21/06 | H15: Produção | Q15: 10 | R15: Equipe bem responsavel e dedicada.
A16: 23 | B16: 46197.629 | C16: 46197.63 | D16: anônima | F16: Agatha | G16: 35º TROFÉU BRASIL DE TRIATHLON - ETAPA 2 - 21/06 | H16: Atendimento | M16: 10 | N16: Elogiado pelo cliente
A17: 24 | B17: 46197.63 | C17: 46197.63 | D17: anônima | F17: Agatha | G17: C.E. INVERNO- MANAUS - 21/06 | H17: Atendimento | M17: 10 | N17: Elogiado pelo cliente
A18: 25 | B18: 46197.63 | C18: 46197.63 | D18: anônima | F18: Agatha | G18: C.E. INVERNO - PORTO ALEGRE - 21/06 | H18: Atendimento | M18: 10 | N18: Elogiado pelo cliente
A19: 26 | B19: 46197.63 | C19: 46197.63 | D19: anônima | F19: Agatha | G19: DESAFIO ENERGIA PETROBRÁS - PASSEIO BIKE - SP - 21/06 | H19: Atendimento | M19: 10 | N19: Elogiado pelo cliente
A20: 27 | B20: 46197.63 | C20: 46197.63 | D20: anônima | F20: Agatha | G20: C.E. INVERNO - FORTALEZA - 21/06 | H20: Atendimento | M20: 10 | N20: Elogiado pelo cliente
A21: 28 | B21: 46197.63 | C21: 46197.63 | D21: anônima | F21: Agatha | G21: SÓ QUERO PEDALAR - RECIFE - 21/06 | H21: Atendimento | M21: 10 | N21: Elogiado pelo cliente
A22: 29 | B22: 46197.63 | C22: 46197.631 | D22: anônima | F22: Agatha | G22: C.E. INVERNO - SÃO JOSÉ DOS CAMPOS - 21/06 | H22: Atendimento | M22: 10 | N22: Elogiado pelo cliente
A23: 30 | B23: 46197.644 | C23: 46197.645 | D23: anônima | F23: Edney Eduardo de Siqueira | G23: SMART FIT - RIO DE JANEIRO - 21/06 | H23: Produção | Q23: 10 | R23: Equipe bem alinhada e comprometida.
A24: 31 | B24: 46197.691 | C24: 46197.697 | D24: anônima | F24: FRED | G24: CORRIDA VALE VITÓRIA | H24: Cenografia | U24: 8 | V24: 9 malotes foram no fundo da carreta atrás de pallets de isotonico que não seriam usados nessa prova. | W24: Sim | Y24: Sim | AA24: Sim | AC24: não | AD24: Sim, houve um grande destaque | AE24: Cenotécnico Bruno Cordeiro - Comandou a marcenaria, reconstruiu back drop do palco, ajudou na modulação de box dos qudros , instalou Back drop dos estandes, além de se prontificar a ajudar em tudo. | AF24: 2. Extraordinário, entregou uma performance espetacular e única!
A25: 32 | B25: 46197.706 | C25: 46197.707 | D25: anônima | F25: Gabriel Bernardineli | G25: Blue run Piracicaba | H25: Cenografia | U25: 10 | V25: Tudo conforme o planejado | W25: Sim | Y25: Sim | AA25: Sim | AC25: Não | AD25: Não, tudo dentro padrão esperado.
A26: 33 | B26: 46197.706 | C26: 46197.708 | D26: anônima | F26: Paulo Roberto da Silva | G26: Urban Walk São paulo13/06/2026 | H26: Cenografia | U26: 10 | V26: Foi bem tranquilo, atendeu todos envolvidos | W26: Sim | Y26: Sim | AA26: Sim | AC26: Não | AD26: Não, tudo dentro padrão esperado.
A27: 34 | B27: 46197.708 | C27: 46197.712 | D27: anônima | F27: FRED | G27: CIRCUITO DE CORRIDAS VALE - SÃO LUÍS - 21/06 | H27: Cenografia | U27: 0 | V27: Sem nota ...foi a carreta que tombou...A carga saiu certinha de Vitória | W27: Sim | Y27: Sim | AA27: Sim | AC27: nao | AD27: Sim, houve um grande destaque | AE27: Bruno Cordeiro - Cenotecnico.... reconstruiu variados tipos de peças que quebraram , ajudou em todos os setores, até bateu grade na madrugada. muito prestativo. | AF27: 2. Extraordinário, entregou uma performance espetacular e única!
A28: 35 | B28: 46198.257 | C28: 46198.258 | D28: anônima | F28: Luciano do Nascimento | G28: 35º TROFÉU BRASIL DE TRIATHLON - ETAPA 2 - 21/06 | H28: Produção | Q28: 10 | R28: Vou dar 10 para a equipe que trabalhou porém eram 2 marceneiros e só foi 1 esse trabalhou por 2
A29: 36 | B29: 46198.618 | C29: 46198.621 | D29: anônima | F29: Camilla Lopes Pereira | G29: SMART FIT - RIO DE JANEIRO - 21/06 | H29: Atendimento | M29: 9 | N29: Não atingiu a nota máxima devido ao estado dos tetos dos stands, principalmente área vip. Marcas brancas com um impacto visual significativo
A30: 37 | B30: 46198.653 | C30: 46198.655 | D30: anônima | F30: Guilherme Flauzino | G30: DESAFIO ENERGIA PETROBRÁS, RIO DE JANEIRO, 14.06.2026 | H30: Cenografia | U30: 10 | V30: TUDO OK | W30: Sim | X30: TUDO OK | Y30: Sim | Z30: TUDO OK | AA30: Sim | AB30: TUDO OK | AC30: falta de windbanner | AD30: Não, tudo dentro padrão esperado.
A31: 38 | B31: 46198.738 | C31: 46198.738 | D31: anônima | F31: Renan Mota | G31: C.E. INVERNO - FORTALEZA - 21/06 | H31: Produção | Q31: 10 | R31: Atendeu conforme o Cronograma ,
A32: 39 | B32: 46201.395 | C32: 46201.402 | D32: anônima | F32: Reinaldo Ribeiro de Sousa | G32: NIGHT RUN - ETAPA 1 - JOINVILLE - 28/06 | H32: Ativação | O32: 6 | P32: Não cortaram bem as pontas dos halleman dos 2x1 teve uma situação durante o evento, que quase machucou o braço do atleta que encostou no 2x1. Não colocaram as rampas nos 2 Stands, e elas nem mesmo estavam na arena, deixaram no caminhão, e o caminhão não estava nem perto da arena. Alguns 2x1 o rolo não estavam esticado, até tive que esticar em alguns, pra não ficar mal apresentado. Só fizeram 5 balcões, sendo que na O.S tinham 6 claramente. Eu ainda os comuniquei na arena para fazer os 6, mas justificaram que o material já estava também dentro do caminhão, não foi feito, e coloquei um mini pranchão para a entrega de kit no GV, para não ficar com desfalque do balcão no quadro de assinaturas.
A33: 40 | B33: 46201.404 | C33: 46201.406 | D33: anônima | F33: Igor Pinheiro | G33: CE inverno - Vitória 28/06/2026 | H33: Ativação | O33: 10 | P33: Entregaram os stands com acabamento bom, não tive nada a pontuar, equipe super atenciosa.
A34: 41 | B34: 46201.405 | C34: 46201.408 | D34: anônima | F34: Myrella Brito Del Freu | G34: C. E. INVERNO - RIBEIRÃO PRETO - 28/06 | H34: Ativação | O34: 5 | P34: Devido à falta de material para montagem, faltou rampa nos estandes, antes de positivar os 2X1 no estandes tive que revisar
A35: 42 | B35: 46201.522 | C35: 46201.523 | D35: anônima | F35: Bruna Cordeiro | G35: CE Inverno BSB | H35: Ativação | O35: 10 | P35: Não precisei pedir para os meninos arrumar nada. Tava tudo bem.
A36: 43 | B36: 46201.532 | C36: 46201.533 | D36: anônima | F36: Natasha Freitas | G36: ECO RUN, POA, 28/06 | H36: Ativação | O36: 8 | P36: Saias dos balcões rasgadas no meio. Porém, ajudaram na falta de capa da tina e deram um acabamento com tecido nos pranchões do Espaço Verde
A37: 44 | B37: 46201.537 | C37: 46201.543 | D37: anônima | F37: Naiara Daiane Souza | G37: Night Run Manaus 27/06 | H37: Ativação | O37: 9 | P37: Como choveu bastante na sexta-feira e o risco de faltar material para os balcões vermelhos a finalização deles ficaram por ultimo
A38: 45 | B38: 46201.624 | C38: 46201.628 | D38: anônima | F38: Marta Andrade | G38: BB SSA- 28.06.26 | H38: Ativação | O38: 5 | P38: Tapadeiras com emendas e acabamento das mesmas muito ruins, palco mal acabado
A39: 46 | B39: 46201.781 | C39: 46201.783 | D39: anônima | F39: Rafael Bispo da Silva | G39: SO QUERO PEDALAR SSA, 28/06 | H39: Ativação | O39: 8 | P39: Algumas colunas estavam levemente rasgadas. O teto tava bem ruim devido o desgaste de uso.
A40: 47 | B40: 46202.305 | C40: 46202.308 | D40: anônima | F40: Raphael Schiabel Telles | G40: Night run Manaus dia 27/06 | H40: Cenografia | U40: 7 | V40: Faltou informação sobre o qu seria usado da carreta de estações , não fomos avisados do que usaríamos da carreta que fica em Manaus , tivemos que descarregar ela inteira pra que pudéssemos achar todos materiais necessários | W40: Sim | X40: Todos com epis | Y40: Sim | Z40: Ok | AA40: Sim | AB40: Equipe muito boa | AC40: Tivemos atrasos dos freelancer de meia hora por motivos de chuva | AD40: Não, tudo dentro do padrão esperado.
...

Sheet Ocorrências
A1: nome | B1: ocorrencia | C1: data
A2: fulano | B2: falta | C2: 46195
A3: cicrano | B3: atraso | C3: 46195
A4: fulano | B4: mérito 1 | C4: 46188
A5: cicrano | B5: mérito 2 | C5: 46175
A6: beltrano | B6: mérito galpão | C6: 46184

Sheet Histórico das Provas
A1: Colaborador | B1: Nota | C1: Eventos | D1: Data | E1: Observação
A2: Kaio Gabriel Ferreira Barbosa | B2: 82 | C2: 42K DE FLORIPA | D2: 46180
A3: Jamerson Rodrigues | B3: 82 | C3: 42K DE FLORIPA | D3: 46180
A4: Cauê Souza Lima | B4: 82 | C4: 42K DE FLORIPA | D4: 46180
A5: Douglas Ferreira dos Reis | B5: 82 | C5: 42K DE FLORIPA | D5: 46180
A6: Erick Ramos da Silva | B6: 86 | C6: GIRL POWER - BELO HORIZONTE | D6: 46180
A7: Willians Silva de Jesus | B7: 86 | C7: GIRL POWER - BELO HORIZONTE | D7: 46180
A8: João Marcos Nascimento Leite | B8: 86 | C8: GIRL POWER - BELO HORIZONTE | D8: 46180
A9: Lyrick Andrade Alves da Silva | B9: 86 | C9: GIRL POWER - BELO HORIZONTE | D9: 46180
A10: Iago Dias Temoteo | B10: 79 | C10: CIRCUITO S RUN - SOROCABA | D10: 46180
A11: Everton De Jesus Marinho Santos | B11: 79 | C11: CIRCUITO S RUN - SOROCABA | D11: 46180
A12: Matheus da Silva Cordeiro | B12: 79 | C12: CIRCUITO S RUN - SOROCABA | D12: 46180
A13: Vinicius da Silva | B13: 79 | C13: CIRCUITO S RUN - SOROCABA | D13: 46180
... A34: Lyrick Andrade Alves da Silva | B34: 83 | C34: CORRIDA VALE - VITÓRIA | D34: 46187
B35: 83.333333 | C35: CIRCUITO DE CORRIDAS VALE - SÃO LUÍS | D35: 46194
B36: 78 | C36: 35º TROFÉU BRASIL DE TRIATHLON - ETAPA 2 | D36: 46194
B37: 80 | C37: C.E. INVERNO- MANAUS | D37: 46194
B38: 72.5 | C38: C.E. INVERNO - PORTO ALEGRE | D38: 46194
B39: 80 | C39: DESAFIO ENERGIA PETROBRÁS - PASSEIO BIKE - SP | D39: 46194
B40: 73.33 | C40: C.E. INVERNO - FORTALEZA | D40: 46194
B41: 80 | C41: SÓ QUERO PEDALAR - RECIFE | D41: 46194
B42: 76 | C42: C.E. INVERNO - SÃO JOSÉ DOS CAMPOS | D42: 46194
B43: 78 | C43: SMART FIT - RIO DE JANEIRO | D43: 46194
B44: 80 | C44: NIGHT RUN - ETAPA 1 - MARINGÁ | D44: 46194

Sheet Matriz modelo
B2: Evento | C2: 42K DE FLORIPA - 07/06
B4: 1 | G4: 2
B5: Conformidade | G5: Performance | O5: RESPOSTAS ORIGINAIS | W5: =C2 -> 42K DE FLORIPA - 07/06
B6: Item | C6: status | D6: Comentários | G6: Item | H6: Peso | I6: Nota | J6: Total | K6: Comentários | O6: Área | P6: Avaliador | Q6: Nota | R6: Comentários - Performance | S6: Conformidade | T6: status | U6: Comentários - Conformidade
B7: Todos usaram EPI na arena? | C7: =T7 | D7: =U7 | E7: =IF(C7="sim",25,0) -> 0 | G7: Carga na saída do galpão | H7: 2 | I7: =Q7 -> 0 | J7: =I7*H7 -> 0 | O7: Cenografia | P7: {=_xlfn.TEXTJOIN(", ", TRUE, _xlfn._xlws.FILTER(Forms!$F:$F, (Forms!$G:$G=$C$2) * (Forms!$H:$H=O7), "Sem avaliador"))} -> Sem avaliador | Q7: {=IFERROR(AVERAGE(_xlfn._xlws.FILTER(IF(ROW(A1)=1, Forms!$U:$U, IF(ROW(A1)=2, Forms!$M:$M, IF(ROW(A1)=3, Forms!$O:$O, IF(ROW(A1)=4, Forms!$Q:$Q, IF(ROW(A1)=5, Forms!$K:$K, Forms!$I:$I))))), (Forms!$G:$G=$C$2) * (Forms!$H:$H=O7), 0)), "")} -> 0 | R7: {=IFERROR(_xlfn.TEXTJOIN("; ", 1, _xlfn._xlws.FILTER(IF(ROW(A1)=1, Forms!$V:$V, IF(ROW(A1)=2, Forms!$N:$N, IF(ROW(A1)=3, Forms!$P:$P, IF(ROW(A1)=4, Forms!$R:$R, IF(ROW(A1)=5, Forms!$L:$L, Forms!$J:$J))))), (Forms!$G:$G=$C$2) * (Forms!$H:$H=O7))), "")} | S7: Todos usaram EPI na arena? | T7: {=IFERROR(IF(ROW(A1)>4, "", _xlfn.TEXTJOIN("; ", 1, _xlfn._xlws.FILTER(IF(ROW(A1)=1, Forms!$W:$W, IF(ROW(A1)=2, Forms!$Y:$Y, IF(ROW(A1)=3, Forms!$AA:$AA, Forms!$S:$S))), (Forms!$G:$G=$C$2) * (TRIM(Forms!$H:$H)=IF(ROW(A1)=4, "Ferramentas e case", "Cenografia"))))), "")} | U7: {=IFERROR(IF(ROW(A1)>4, "", _xlfn.TEXTJOIN("; ", 1, _xlfn._xlws.FILTER(IF(ROW(A1)=1, Forms!$X:$X, IF(ROW(A1)=2, Forms!$Z:$Z, IF(ROW(A1)=3, Forms!$AB:$AB, Forms!$T:$T))), (Forms!$G:$G=$C$2) * (Forms!$H:$H=IF(ROW(A1)=4, $O$12, $O$7))))), "")} | X7: =$Q$26 -> 0
B8: Estaiamento e Aterramento foram feitos de maneira correta? | C8: =T8 | D8: =U8 | E8: =IF(C8="sim",25,0) -> 0 | G8: Qualidade da entrega | H8: 3 | I8: =Q8 -> 0 | J8: =I8*H8 -> 0 | O8: Atendimento | P8: {=_xlfn.TEXTJOIN(", ", TRUE, _xlfn._xlws.FILTER(Forms!$F:$F, (Forms!$G:$G=$C$2) * (Forms!$H:$H=O8), "Sem avaliador"))} -> Sem avaliador | Q8: {=IFERROR(AVERAGE(_xlfn._xlws.FILTER(IF(ROW(A2)=1, Forms!$U:$U, IF(ROW(A2)=2, Forms!$M:$M, IF(ROW(A2)=3, Forms!$O:$O, IF(ROW(A2)=4, Forms!$Q:$Q, IF(ROW(A2)=5, Forms!$K:$K, Forms!$I:$I))))), (Forms!$G:$G=$C$2) * (Forms!$H:$H=O8), 0)), "")} -> 0 | R8: {=IFERROR(_xlfn.TEXTJOIN("; ", 1, _xlfn._xlws.FILTER(IF(ROW(A2)=1, Forms!$V:$V, IF(ROW(A2)=2, Forms!$N:$N, IF(ROW(A2)=3, Forms!$P:$P, IF(ROW(A2)=4, Forms!$R:$R, IF(ROW(A2)=5, Forms!$L:$L, Forms!$J:$J))))), (Forms!$G:$G=$C$2) * (Forms!$H:$H=O8))), "")} | S8: Estaiamento e Aterramento foram feitos de maneira correta? | T8: {=IFERROR(IF(ROW(A2)>4, "", _xlfn.TEXTJOIN("; ", 1, _xlfn._xlws.FILTER(IF(ROW(A2)=1, Forms!$W:$W, IF(ROW(A2)=2, Forms!$Y:$Y, IF(ROW(A2)=3, Forms!$AA:$AA, Forms!$S:$S))), (Forms!$G:$G=$C$2) * (TRIM(Forms!$H:$H)=IF(ROW(A2)=4, "Ferramentas e case", "Cenografia"))))), "")} | U8: {=IFERROR(IF(ROW(A2)>4, "", _xlfn.TEXTJOIN("; ", 1, _xlfn._xlws.FILTER(IF(ROW(A2)=1, Forms!$X:$X, IF(ROW(A2)=2, Forms!$Z:$Z, IF(ROW(A2)=3, Forms!$AB:$AB, Forms!$T:$T))), (Forms!$G:$G=$C$2) * (Forms!$H:$H=IF(ROW(A2)=4, $O$12, $O$7))))), "")} | X8: =$Q$26 -> 0
B9: Conduta e comportamento foram adequados? | C9: =T9 | D9: =U9 | E9: =IF(C9="sim",25,0) -> 0 | G9: Qualidade da entrega 2 | H9: 3 | I9: =Q9 -> 0 | J9: =I9*H9 -> 0 | O9: Ativação | P9: {=_xlfn.TEXTJOIN(", ", TRUE, _xlfn._xlws.FILTER(Forms!$F:$F, (Forms!$G:$G=$C$2) * (Forms!$H:$H=O9), "Sem avaliador"))} -> Sem avaliador | Q9: {=IFERROR(AVERAGE(_xlfn._xlws.FILTER(IF(ROW(A3)=1, Forms!$U:$U, IF(ROW(A3)=2, Forms!$M:$M, IF(ROW(A3)=3, Forms!$O:$O, IF(ROW(A3)=4, Forms!$Q:$Q, IF(ROW(A3)=5, Forms!$K:$K, Forms!$I:$I))))), (Forms!$G:$G=$C$2) * (Forms!$H:$H=O9), 0)), "")} -> 0 | R9: {=IFERROR(_xlfn.TEXTJOIN("; ", 1, _xlfn._xlws.FILTER(IF(ROW(A3)=1, Forms!$V:$V, IF(ROW(A3)=2, Forms!$N:$N, IF(ROW(A3)=3, Forms!$P:$P, IF(ROW(A3)=4, Forms!$R:$R, IF(ROW(A3)=5, Forms!$L:$L, Forms!$J:$J))))), (Forms!$G:$G=$C$2) * (Forms!$H:$H=O9))), "")} | S9: Conduta e comportamento foram adequados? | T9: {=IFERROR(IF(ROW(A3)>4, "", _xlfn.TEXTJOIN("; ", 1, _xlfn._xlws.FILTER(IF(ROW(A3)=1, Forms!$W:$W, IF(ROW(A3)=2, Forms!$Y:$Y, IF(ROW(A3)=3, Forms!$AA:$AA, Forms!$S:$S))), (Forms!$G:$G=$C$2) * (TRIM(Forms!$H:$H)=IF(ROW(A3)=4, "Ferramentas e case", "Cenografia"))))), "")} | U9: {=IFERROR(IF(ROW(A3)>4, "", _xlfn.TEXTJOIN("; ", 1, _xlfn._xlws.FILTER(IF(ROW(A3)=1, Forms!$X:$X, IF(ROW(A3)=2, Forms!$Z:$Z, IF(ROW(A3)=3, Forms!$AB:$AB, Forms!$T:$T))), (Forms!$G:$G=$C$2) * (Forms!$H:$H=IF(ROW(A3)=4, $O$12, $O$7))))), "")} | X9: =$Q$26 -> 0
B10: Todos os equipamentos e ferramentas retornaram? | C10: =T10 | D10: =U10 | E10: =IF(C10="sim",25,0) -> 0 | G10: Prazo de entrega | H10: 2 | I10: =Q10 -> 0 | J10: =I10*H10 -> 0 | O10: Produção | P10: {=_xlfn.TEXTJOIN(", ", TRUE, _xlfn._xlws.FILTER(Forms!$F:$F, (Forms!$G:$G=$C$2) * (Forms!$H:$H=O10), "Sem avaliador"))} -> Sem avaliador | Q10: {=IFERROR(AVERAGE(_xlfn._xlws.FILTER(IF(ROW(A4)=1, Forms!$U:$U, IF(ROW(A4)=2, Forms!$M:$M, IF(ROW(A4)=3, Forms!$O:$O, IF(ROW(A4)=4, Forms!$Q:$Q, IF(ROW(A4)=5, Forms!$K:$K, Forms!$I:$I))))), (Forms!$G:$G=$C$2) * (Forms!$H:$H=O10), 0)), "")} -> 0 | R10: {=IFERROR(_xlfn.TEXTJOIN("; ", 1, _xlfn._xlws.FILTER(IF(ROW(A4)=1, Forms!$V:$V, IF(ROW(A4)=2, Forms!$N:$N, IF(ROW(A4)=3, Forms!$P:$P, IF(ROW(A4)=4, Forms!$R:$R, IF(ROW(A4)=5, Forms!$L:$L, Forms!$J:$J))))), (Forms!$G:$G=$C$2) * (Forms!$H:$H=O10))), "")} | S10: Todos os equipamentos e ferramentas retornaram? | T10: {=IFERROR(_xlfn.TEXTJOIN("; ", 1, _xlfn._xlws.FILTER(Forms!$S:$S, (Forms!$G:$G=$C$2) * (Forms!$H:$H="Ferramentas e Case (Cenografia)"))), "")} | U10: {=IFERROR(_xlfn.TEXTJOIN("; ", 1, _xlfn._xlws.FILTER(Forms!$T:$T, (Forms!$G:$G=$C$2) * (Forms!$H:$H="Ferramentas e Case (Cenografia)"))), "")} | X10: =$Q$26 -> 0
E11: =SUM(E7:E10) -> 0 | G11: Logistica Reversa | H11: 2 | I11: =Q11 -> 0 | J11: =I11*H11 -> 0 | O11: Logística | P11: {=_xlfn.TEXTJOIN(", ", TRUE, _xlfn._xlws.FILTER(Forms!$F:$F, (Forms!$G:$G=$C$2) * (Forms!$H:$H=O11), "Sem avaliador"))} -> Sem avaliador | Q11: {=IFERROR(AVERAGE(_xlfn._xlws.FILTER(IF(ROW(A5)=1, Forms!$U:$U, IF(ROW(A5)=2, Forms!$M:$M, IF(ROW(A5)=3, Forms!$O:$O, IF(ROW(A5)=4, Forms!$Q:$Q, IF(ROW(A5)=5, Forms!$K:$K, Forms!$I:$I))))), (Forms!$G:$G=$C$2) * (Forms!$H:$H=O11), 0)), "")} -> 0 | R11: {=IFERROR(_xlfn.TEXTJOIN("; ", 1, _xlfn._xlws.FILTER(IF(ROW(A5)=1, Forms!$V:$V, IF(ROW(A5)=2, Forms!$N:$N, IF(ROW(A5)=3, Forms!$P:$P, IF(ROW(A5)=4, Forms!$R:$R, IF(ROW(A5)=5, Forms!$L:$L, Forms!$J:$J))))), (Forms!$G:$G=$C$2) * (Forms!$H:$H=O11))), "")} | S11: Houveram atrasos ou faltas? | T11: {=IFERROR(_xlfn.TEXTJOIN("; ", 1, _xlfn._xlws.FILTER(Forms!$S:$S, (Forms!$G:$G=$C$2) * (Forms!$H:$H="Ferramentas e Case (Cenografia)"))), "")} | U11: {=IFERROR(_xlfn.TEXTJOIN("; ", 1, _xlfn._xlws.FILTER(Forms!$T:$T, (Forms!$G:$G=$C$2) * (Forms!$H:$H="Ferramentas e Case (Cenografia)"))), "")} | X11: =$Q$26 -> 0
G12: Perda de material/estrutura | H12: 2 | I12: =Q12 -> 0 | J12: =I12*H12 -> 0 | O12: Logística | P12: {=_xlfn.TEXTJOIN(", ", TRUE, _xlfn._xlws.FILTER(Forms!$F:$F, (Forms!$G:$G=$C$2) * (Forms!$H:$H=O12), "Sem avaliador"))} -> Sem avaliador | Q12: {=IFERROR(AVERAGE(_xlfn._xlws.FILTER(IF(ROW(A6)=1, Forms!$U:$U, IF(ROW(A6)=2, Forms!$M:$M, IF(ROW(A6)=3, Forms!$O:$O, IF(ROW(A6)=4, Forms!$Q:$Q, IF(ROW(A6)=5, Forms!$K:$K, Forms!$I:$I))))), (Forms!$G:$G=$C$2) * (Forms!$H:$H=O12), 0)), "")} -> 0 | R12: {=IFERROR(_xlfn.TEXTJOIN("; ", 1, _xlfn._xlws.FILTER(IF(ROW(A6)=1, Forms!$V:$V, IF(ROW(A6)=2, Forms!$N:$N, IF(ROW(A6)=3, Forms!$P:$P, IF(ROW(A6)=4, Forms!$R:$R, IF(ROW(A6)=5, Forms!$L:$L, Forms!$J:$J))))), (Forms!$G:$G=$C$2) * (Forms!$H:$H=O12))), "")} | S12: Desempenho para mérito? | X12: =$Q$26 -> 0
B13: Conformidade | D13: {=_xlfn.IFS(E11=100, "100%", E11=75, "-10 pontos", E11=50, "-20 pontos", E11=25, "-30 pontos", E11=0, "-40 pontos")} -> -40 pontos | G13: Performance | I13: =SUM(J7:J12)/SUM(H7:H12)*10 -> 0
B15: Pontuação final do Evento | F15: =I13+((E11-100)/2.5) -> -40

Sheet Matriz
B2: Evento | C2: TESTE outono
B4: 1 | F4: 2
B5: Conformidade | F5: Performance | N5: RESPOSTAS ORIGINAIS | V5: =C2 -> TESTE outono
B6: Item | C6: status | F6: Item | G6: Peso | H6: Nota | I6: Total | J6: Comentários | N6: Área | O6: Avaliador | P6: Nota | Q6: Comentários - Performance | R6: Conformidade | S6: status | T6: Comentários - Conformidade
B7: Todos usaram EPI na arena? | C7: =S7 | D7: =IF(C7="sim",25,0) -> 0 | F7: Carga na saída do galpão | G7: 2 | H7: =P7 -> 0 | I7: =H7*G7 -> 0 | N7: Cenografia | O7: {=_xlfn.TEXTJOIN(", ", TRUE, _xlfn._xlws.FILTER(Forms!$F:$F, (Forms!$G:$G=$C$2) * (Forms!$H:$H=N7), "Sem avaliador"))} -> Sem avaliador | P7: {=IFERROR(AVERAGE(_xlfn._xlws.FILTER(IF(ROW(A1)=1, Forms!$U:$U, IF(ROW(A1)=2, Forms!$M:$M, IF(ROW(A1)=3, Forms!$O:$O, IF(ROW(A1)=4, Forms!$Q:$Q, IF(ROW(A1)=5, Forms!$K:$K, Forms!$I:$I))))), (Forms!$G:$G=$C$2) * (Forms!$H:$H=N7), 0)), "")} -> 0 | Q7: {=IFERROR(_xlfn.TEXTJOIN("; ", 1, _xlfn._xlws.FILTER(IF(ROW(A1)=1, Forms!$V:$V, IF(ROW(A1)=2, Forms!$N:$N, IF(ROW(A1)=3, Forms!$P:$P, IF(ROW(A1)=4, Forms!$R:$R, IF(ROW(A1)=5, Forms!$L:$L, Forms!$J:$J))))), (Forms!$G:$G=$C$2) * (Forms!$H:$H=N7))), "")} | R7: Todos usaram EPI na arena? | S7: {=IFERROR(IF(ROW(A1)>4, "", _xlfn.TEXTJOIN("; ", 1, _xlfn._xlws.FILTER(IF(ROW(A1)=1, Forms!$W:$W, IF(ROW(A1)=2, Forms!$Y:$Y, IF(ROW(A1)=3, Forms!$AA:$AA, Forms!$S:$S))), (Forms!$G:$G=$C$2) * (TRIM(Forms!$H:$H)=IF(ROW(A1)=4, "Ferramentas e case", "Cenografia"))))), "")} | T7: {=IFERROR(IF(ROW(A1)>4, "", _xlfn.TEXTJOIN("; ", 1, _xlfn._xlws.FILTER(IF(ROW(A1)=1, Forms!$X:$X, IF(ROW(A1)=2, Forms!$Z:$Z, IF(ROW(A1)=3, Forms!$AB:$AB, Forms!$T:$T))), (Forms!$G:$G=$C$2) * (Forms!$H:$H=IF(ROW(A1)=4, $N$12, $N$7))))), "")} | W7: =$P$26 -> 0
B8: Estaiamento e Aterramento foram feitos de maneira correta? | C8: =S8 | D8: =IF(C8="sim",25,0) -> 0 | F8: Qualidade da entrega | G8: 3 | H8: =P8 -> 0 | I8: =H8*G8 -> 0 | N8: Atendimento | O8: {=_xlfn.TEXTJOIN(", ", TRUE, _xlfn._xlws.FILTER(Forms!$F:$F, (Forms!$G:$G=$C$2) * (Forms!$H:$H=N8), "Sem avaliador"))} -> Sem avaliador | P8: {=IFERROR(AVERAGE(_xlfn._xlws.FILTER(IF(ROW(A2)=1, Forms!$U:$U, IF(ROW(A2)=2, Forms!$M:$M, IF(ROW(A2)=3, Forms!$O:$O, IF(ROW(A2)=4, Forms!$Q:$Q, IF(ROW(A2)=5, Forms!$K:$K, Forms!$I:$I))))), (Forms!$G:$G=$C$2) * (Forms!$H:$H=N8), 0)), "")} -> 0 | Q8: {=IFERROR(_xlfn.TEXTJOIN("; ", 1, _xlfn._xlws.FILTER(IF(ROW(A2)=1, Forms!$V:$V, IF(ROW(A2)=2, Forms!$N:$N, IF(ROW(A2)=3, Forms!$P:$P, IF(ROW(A2)=4, Forms!$R:$R, IF(ROW(A2)=5, Forms!$L:$L, Forms!$J:$J))))), (Forms!$G:$G=$C$2) * (Forms!$H:$H=N8))), "")} | R8: Estaiamento e Aterramento foram feitos de maneira correta? | S8: {=IFERROR(IF(ROW(A2)>4, "", _xlfn.TEXTJOIN("; ", 1, _xlfn._xlws.FILTER(IF(ROW(A2)=1, Forms!$W:$W, IF(ROW(A2)=2, Forms!$Y:$Y, IF(ROW(A2)=3, Forms!$AA:$AA, Forms!$S:$S))), (Forms!$G:$G=$C$2) * (TRIM(Forms!$H:$H)=IF(ROW(A2)=4, "Ferramentas e case", "Cenografia"))))), "")} | T8: {=IFERROR(IF(ROW(A2)>4, "", _xlfn.TEXTJOIN("; ", 1, _xlfn._xlws.FILTER(IF(ROW(A2)=1, Forms!$X:$X, IF(ROW(A2)=2, Forms!$Z:$Z, IF(ROW(A2)=3, Forms!$AB:$AB, Forms!$T:$T))), (Forms!$G:$G=$C$2) * (Forms!$H:$H=IF(ROW(A2)=4, $N$12, $N$7))))), "")} | W8: =$P$26 -> 0
B9: Conduta e comportamento foram adequados? | C9: =S9 | D9: =IF(C9="sim",25,0) -> 0 | F9: Qualidade da entrega 2 | G9: 3 | H9: =P9 -> 0 | I9: =H9*G9 -> 0 | N9: Ativação | O9: {=_xlfn.TEXTJOIN(", ", TRUE, _xlfn._xlws.FILTER(Forms!$F:$F, (Forms!$G:$G=$C$2) * (Forms!$H:$H=N9), "Sem avaliador"))} -> Sem avaliador | P9: {=IFERROR(AVERAGE(_xlfn._xlws.FILTER(IF(ROW(A3)=1, Forms!$U:$U, IF(ROW(A3)=2, Forms!$M:$M, IF(ROW(A3)=3, Forms!$O:$O, IF(ROW(A3)=4, Forms!$Q:$Q, IF(ROW(A3)=5, Forms!$K:$K, Forms!$I:$I))))), (Forms!$G:$G=$C$2) * (Forms!$H:$H=N9), 0)), "")} -> 0 | Q9: {=IFERROR(_xlfn.TEXTJOIN("; ", 1, _xlfn._xlws.FILTER(IF(ROW(A3)=1, Forms!$V:$V, IF(ROW(A3)=2, Forms!$N:$N, IF(ROW(A3)=3, Forms!$P:$P, IF(ROW(A3)=4, Forms!$R:$R, IF(ROW(A3)=5, Forms!$L:$L, Forms!$J:$J))))), (Forms!$G:$G=$C$2) * (Forms!$H:$H=N9))), "")} | R9: Conduta e comportamento foram adequados? | S9: {=IFERROR(IF(ROW(A3)>4, "", _xlfn.TEXTJOIN("; ", 1, _xlfn._xlws.FILTER(IF(ROW(A3)=1, Forms!$W:$W, IF(ROW(A3)=2, Forms!$Y:$Y, IF(ROW(A3)=3, Forms!$AA:$AA, Forms!$S:$S))), (Forms!$G:$G=$C$2) * (TRIM(Forms!$H:$H)=IF(ROW(A3)=4, "Ferramentas e case", "Cenografia"))))), "")} | T9: {=IFERROR(IF(ROW(A3)>4, "", _xlfn.TEXTJOIN("; ", 1, _xlfn._xlws.FILTER(IF(ROW(A3)=1, Forms!$X:$X, IF(ROW(A3)=2, Forms!$Z:$Z, IF(ROW(A3)=3, Forms!$AB:$AB, Forms!$T:$T))), (Forms!$G:$G=$C$2) * (Forms!$H:$H=IF(ROW(A3)=4, $N$12, $N$7))))), "")} | W9: =$P$26 -> 0
B10: Todos os equipamentos e ferramentas retornaram? | C10: =S10 | D10: =IF(C10="sim",25,0) -> 0 | F10: Prazo de entrega | G10: 2 | H10: =P10 -> 0 | I10: =H10*G10 -> 0 | N10: Produção | O10: {=_xlfn.TEXTJOIN(", ", TRUE, _xlfn._xlws.FILTER(Forms!$F:$F, (Forms!$G:$G=$C$2) * (Forms!$H:$H=N10), "Sem avaliador"))} -> Sem avaliador | P10: {=IFERROR(AVERAGE(_xlfn._xlws.FILTER(IF(ROW(A4)=1, Forms!$U:$U, IF(ROW(A4)=2, Forms!$M:$M, IF(ROW(A4)=3, Forms!$O:$O, IF(ROW(A4)=4, Forms!$Q:$Q, IF(ROW(A4)=5, Forms!$K:$K, Forms!$I:$I))))), (Forms!$G:$G=$C$2) * (Forms!$H:$H=N10), 0)), "")} -> 0 | Q10: {=IFERROR(_xlfn.TEXTJOIN("; ", 1, _xlfn._xlws.FILTER(IF(ROW(A4)=1, Forms!$V:$V, IF(ROW(A4)=2, Forms!$N:$N, IF(ROW(A4)=3, Forms!$P:$P, IF(ROW(A4)=4, Forms!$R:$R, IF(ROW(A4)=5, Forms!$L:$L, Forms!$J:$J))))), (Forms!$G:$G=$C$2) * (Forms!$H:$H=N10))), "")} | R10: Todos os equipamentos e ferramentas retornaram? | S10: {=IFERROR(_xlfn.TEXTJOIN("; ", 1, _xlfn._xlws.FILTER(Forms!$S:$S, (Forms!$G:$G=$C$2) * (Forms!$H:$H="Ferramentas e Case (Cenografia)"))), "")} | T10: {=IFERROR(_xlfn.TEXTJOIN("; ", 1, _xlfn._xlws.FILTER(Forms!$T:$T, (Forms!$G:$G=$C$2) * (Forms!$H:$H="Ferramentas e Case (Cenografia)"))), "")} | W10: =$P$26 -> 0
B11: Conformidade | C11: {=_xlfn.IFS(D11=100, "100%", D11=75, "-10 pontos", D11=50, "-20 pontos", D11=25, "-30 pontos", D11=0, "-40 pontos")} -> -40 pontos | D11: =SUM(D7:D10) -> 0 | F11: Logistica Reversa | G11: 2 | H11: =P11 -> 0 | I11: =H11*G11 -> 0 | N11: Logística | O11: {=_xlfn.TEXTJOIN(", ", TRUE, _xlfn._xlws.FILTER(Forms!$F:$F, (Forms!$G:$G=$C$2) * (Forms!$H:$H=N11), "Sem avaliador"))} -> Sem avaliador | P11: {=IFERROR(AVERAGE(_xlfn._xlws.FILTER(IF(ROW(A5)=1, Forms!$U:$U, IF(ROW(A5)=2, Forms!$M:$M, IF(ROW(A5)=3, Forms!$O:$O, IF(ROW(A5)=4, Forms!$Q:$Q, IF(ROW(A5)=5, Forms!$K:$K, Forms!$I:$I))))), (Forms!$G:$G=$C$2) * (Forms!$H:$H=N11), 0)), "")} -> 0 | Q11: {=IFERROR(_xlfn.TEXTJOIN("; ", 1, _xlfn._xlws.FILTER(IF(ROW(A5)=1, Forms!$V:$V, IF(ROW(A5)=2, Forms!$N:$N, IF(ROW(A5)=3, Forms!$P:$P, IF(ROW(A5)=4, Forms!$R:$R, IF(ROW(A5)=5, Forms!$L:$L, Forms!$J:$J))))), (Forms!$G:$G=$C$2) * (Forms!$H:$H=N11))), "")} | R11: Houveram atrasos ou faltas? | S11: {=IFERROR(_xlfn.TEXTJOIN("; ", 1, _xlfn._xlws.FILTER(Forms!$S:$S, (Forms!$G:$G=$C$2) * (Forms!$H:$H="Ferramentas e Case (Cenografia)"))), "")} | T11: {=IFERROR(_xlfn.TEXTJOIN("; ", 1, _xlfn._xlws.FILTER(Forms!$T:$T, (Forms!$G:$G=$C$2) * (Forms!$H:$H="Ferramentas e Case (Cenografia)"))), "")} | W11: =$P$26 -> 0
F12: Perda de material/estrutura | G12: 2 | H12: =P12 -> 0 | I12: =H12*G12 -> 0 | N12: Logística | O12: {=_xlfn.TEXTJOIN(", ", TRUE, _xlfn._xlws.FILTER(Forms!$F:$F, (Forms!$G:$G=$C$2) * (Forms!$H:$H=N12), "Sem avaliador"))} -> Sem avaliador | P12: {=IFERROR(AVERAGE(_xlfn._xlws.FILTER(IF(ROW(A6)=1, Forms!$U:$U, IF(ROW(A6)=2, Forms!$M:$M, IF(ROW(A6)=3, Forms!$O:$O, IF(ROW(A6)=4, Forms!$Q:$Q, IF(ROW(A6)=5, Forms!$K:$K, Forms!$I:$I))))), (Forms!$G:$G=$C$2) * (Forms!$H:$H=N12), 0)), "")} -> 0 | Q12: {=IFERROR(_xlfn.TEXTJOIN("; ", 1, _xlfn._xlws.FILTER(IF(ROW(A6)=1, Forms!$V:$V, IF(ROW(A6)=2, Forms!$N:$N, IF(ROW(A6)=3, Forms!$P:$P, IF(ROW(A6)=4, Forms!$R:$R, IF(ROW(A6)=5, Forms!$L:$L, Forms!$J:$J))))), (Forms!$G:$G=$C$2) * (Forms!$H:$H=N12))), "")} | R12: Desempenho para mérito? | W12: =$P$26 -> 0
F13: Performance | H13: =SUM(I7:I12)/SUM(G7:G12)*10 -> 0
F15: Pontuação final do Evento
F16: =H13+((D11-100)/2.5) -> -40

Sheet Tabela
A1: Data | B1: (Tudo)
A2: Eventos | B2: (Tudo)
A4: Colaborador | B4: Soma de Nota | C4: Contagem de Eventos | D4: Pontos de mérito | E4: Atrasos e Faltas | F4: Média | G4: Pelotão | H4: Bônus Cajú
A5: Adriano Silva De Araujo | B5: 85 | C5: 1 | F5: =((B5+D5)-E5)/C5 -> 85 | G5: {=_xlfn.IFS(F5<70, "Branco", F5<80, "Verde", F5<90, "Azul", TRUE, "Quênia")} -> Azul | H5: {=_xlfn.IFS(F5<70, 0, F5<80, 1600, F5<90, 2400, TRUE, 3200)} -> 2400
A6: Alonso Lucas Trindade | B6: 78 | C6: 1 | F6: =((B6+D6)-E6)/C6 -> 78 | G6: {=_xlfn.IFS(F6<70, "Branco", F6<80, "Verde", F6<90, "Azul", TRUE, "Quênia")} -> Verde | H6: {=_xlfn.IFS(F6<70, 0, F6<80, 1600, F6<90, 2400, TRUE, 3200)} -> 1600
A7: Bruno da Silva Cordeiro | B7: 83 | C7: 1 | F7: =((B7+D7)-E7)/C7 -> 83 | G7: {=_xlfn.IFS(F7<70, "Branco", F7<80, "Verde", F7<90, "Azul", TRUE, "Quênia")} -> Azul | H7: {=_xlfn.IFS(F7<70, 0, F7<80, 1600, F7<90, 2400, TRUE, 3200)} -> 2400
A8: Cauê Souza Lima | B8: 160 | C8: 2 | F8: =((B8+D8)-E8)/C8 -> 80 | G8: {=_xlfn.IFS(F8<70, "Branco", F8<80, "Verde", F8<90, "Azul", TRUE, "Quênia")} -> Azul | H8: {=_xlfn.IFS(F8<70, 0, F8<80, 1600, F8<90, 2400, TRUE, 3200)} -> 2400
A9: Douglas Ferreira dos Reis | B9: 167 | C9: 2 | F9: =((B9+D9)-E9)/C9 -> 83.5 | G9: {=_xlfn.IFS(F9<70, "Branco", F9<80, "Verde", F9<90, "Azul", TRUE, "Quênia")} -> Azul | H9: {=_xlfn.IFS(F9<70, 0, F9<80, 1600, F9<90, 2400, TRUE, 3200)} -> 2400
A10: Erick Ramos da Silva | B10: 171 | C10: 2 | F10: =((B10+D10)-E10)/C10 -> 85.5 | G10: {=_xlfn.IFS(F10<70, "Branco", F10<80, "Verde", F10<90, "Azul", TRUE, "Quênia")} -> Azul | H10: {=_xlfn.IFS(F10<70, 0, F10<80, 1600, F10<90, 2400, TRUE, 3200)} -> 2400
A11: Ernande Liniki Andrade Alves da Silva | B11: 71 | C11: 1 | F11: =((B11+D11)-E11)/C11 -> 71 | G11: {=_xlfn.IFS(F11<70, "Branco", F11<80, "Verde", F11<90, "Azul", TRUE, "Quênia")} -> Verde | H11: {=_xlfn.IFS(F11<70, 0, F11<80, 1600, F11<90, 2400, TRUE, 3200)} -> 1600
A12: Everton De Jesus Marinho Santos | B12: 162 | C12: 2 | F12: =((B12+D12)-E12)/C12 -> 81 | G12: {=_xlfn.IFS(F12<70, "Branco", F12<80, "Verde", F12<90, "Azul", TRUE, "Quênia")} -> Azul | H12: {=_xlfn.IFS(F12<70, 0, F12<80, 1600, F12<90, 2400, TRUE, 3200)} -> 2400
A13: Gabriel Nascimento Menezes | B13: 85 | C13: 1 | F13: =((B13+D13)-E13)/C13 -> 85 | G13: {=_xlfn.IFS(F13<70, "Branco", F13<80, "Verde", F13<90, "Azul", TRUE, "Quênia")} -> Azul | H13: {=_xlfn.IFS(F13<70, 0, F13<80, 1600, F13<90, 2400, TRUE, 3200)} -> 2400
A14: Iago Dias Temoteo | B14: 150 | C14: 2 | F14: =((B14+D14)-E14)/C14 -> 75 | G14: {=_xlfn.IFS(F14<70, "Branco", F14<80, "Verde", F14<90, "Azul", TRUE, "Quênia")} -> Verde | H14: {=_xlfn.IFS(F14<70, 0, F14<80, 1600, F14<90, 2400, TRUE, 3200)} -> 1600
A15: Jamerson Rodrigues | B15: 153 | C15: 2 | F15: =((B15+D15)-E15)/C15 -> 76.5 | G15: {=_xlfn.IFS(F15<70, "Branco", F15<80, "Verde", F15<90, "Azul", TRUE, "Quênia")} -> Verde | H15: {=_xlfn.IFS(F15<70, 0, F15<80, 1600, F15<90, 2400, TRUE, 3200)} -> 1600
A16: João Marcos Nascimento Leite | B16: 164 | C16: 2 | F16: =((B16+D16)-E16)/C16 -> 82 | G16: {=_xlfn.IFS(F16<70, "Branco", F16<80, "Verde", F16<90, "Azul", TRUE, "Quênia")} -> Azul | H16: {=_xlfn.IFS(F16<70, 0, F16<80, 1600, F16<90, 2400, TRUE, 3200)} -> 2400
... A23: Willians Silva de Jesus | B23: 163 | C23: 2 | F23: =((B23+D23)-E23)/C23 -> 81.5 | G23: {=_xlfn.IFS(F23<70, "Branco", F23<80, "Verde", F23<90, "Azul", TRUE, "Quênia")} -> Azul | H23: {=_xlfn.IFS(F23<70, 0, F23<80, 1600, F23<90, 2400, TRUE, 3200)} -> 2400
A24: Total Geral | B24: 2643 | C24: 33 | H24: =SUM(H5:H24) -> 37333.333

Sheet Pendentes
A1: EVENTO | B1: Atendimento | C1: Ativação | D1: Logística | E1: Ferramentas e Case (Cenografia) | F1: Produção | G1: Cenografia
A2: NIGHT RUN - ETAPA 1 - JOINVILLE - 28/06 | B2: =IF(COUNTIFS(Forms!$G:$G, $A2, Forms!$H:$H, B$1) > 0, "ok", "pendente") -> ok | C2: =IF(COUNTIFS(Forms!$G:$G, $A2, Forms!$H:$H, C$1) > 0, "ok", "pendente") -> ok | D2: =IF(COUNTIFS(Forms!$G:$G, $A2, Forms!$H:$H, D$1) > 0, "ok", "pendente") -> ok | E2: =IF(COUNTIFS(Forms!$G:$G, $A2, Forms!$H:$H, E$1) > 0, "ok", "pendente") -> ok | F2: =IF(COUNTIFS(Forms!$G:$G, $A2, Forms!$H:$H, F$1) > 0, "ok", "pendente") -> ok | G2: =IF(COUNTIFS(Forms!$G:$G, $A2, Forms!$H:$H, G$1) > 0, "ok", "pendente") -> pendente
A3: NIGHT RUN - ETAPA 1 - MANAUS - 28/06 | B3: =IF(COUNTIFS(Forms!$G:$G, $A3, Forms!$H:$H, B$1) > 0, "ok", "pendente") -> ok | C3: =IF(COUNTIFS(Forms!$G:$G, $A3, Forms!$H:$H, C$1) > 0, "ok", "pendente") -> pendente | D3: =IF(COUNTIFS(Forms!$G:$G, $A3, Forms!$H:$H, D$1) > 0, "ok", "pendente") -> pendente | E3: =IF(COUNTIFS(Forms!$G:$G, $A3, Forms!$H:$H, E$1) > 0, "ok", "pendente") -> ok | F3: =IF(COUNTIFS(Forms!$G:$G, $A3, Forms!$H:$H, F$1) > 0, "ok", "pendente") -> pendente | G3: =IF(COUNTIFS(Forms!$G:$G, $A3, Forms!$H:$H, G$1) > 0, "ok", "pendente") -> pendente
A4: C. E. INVERNO - RIBEIRÃO PRETO - 28/06 | B4: =IF(COUNTIFS(Forms!$G:$G, $A4, Forms!$H:$H, B$1) > 0, "ok", "pendente") -> ok | C4: =IF(COUNTIFS(Forms!$G:$G, $A4, Forms!$H:$H, C$1) > 0, "ok", "pendente") -> ok | D4: =IF(COUNTIFS(Forms!$G:$G, $A4, Forms!$H:$H, D$1) > 0, "ok", "pendente") -> ok | E4: =IF(COUNTIFS(Forms!$G:$G, $A4, Forms!$H:$H, E$1) > 0, "ok", "pendente") -> ok | F4: =IF(COUNTIFS(Forms!$G:$G, $A4, Forms!$H:$H, F$1) > 0, "ok", "pendente") -> ok | G4: =IF(COUNTIFS(Forms!$G:$G, $A4, Forms!$H:$H, G$1) > 0, "ok", "pendente") -> pendente
A5: C.E. INVERNO - BRASÍLIA - 28/06 | B5: =IF(COUNTIFS(Forms!$G:$G, $A5, Forms!$H:$H, B$1) > 0, "ok", "pendente") -> ok | C5: =IF(COUNTIFS(Forms!$G:$G, $A5, Forms!$H:$H, C$1) > 0, "ok", "pendente") -> pendente | D5: =IF(COUNTIFS(Forms!$G:$G, $A5, Forms!$H:$H, D$1) > 0, "ok", "pendente") -> pendente | E5: =IF(COUNTIFS(Forms!$G:$G, $A5, Forms!$H:$H, E$1) > 0, "ok", "pendente") -> ok | F5: =IF(COUNTIFS(Forms!$G:$G, $A5, Forms!$H:$H, F$1) > 0, "ok", "pendente") -> ok | G5: =IF(COUNTIFS(Forms!$G:$G, $A5, Forms!$H:$H, G$1) > 0, "ok", "pendente") -> pendente
A6: C.E. INVERNO - SÃO PAULO - 28/06 | B6: =IF(COUNTIFS(Forms!$G:$G, $A6, Forms!$H:$H, B$1) > 0, "ok", "pendente") -> ok | C6: =IF(COUNTIFS(Forms!$G:$G, $A6, Forms!$H:$H, C$1) > 0, "ok", "pendente") -> pendente | D6: =IF(COUNTIFS(Forms!$G:$G, $A6, Forms!$H:$H, D$1) > 0, "ok", "pendente") -> pendente | E6: =IF(COUNTIFS(Forms!$G:$G, $A6, Forms!$H:$H, E$1) > 0, "ok", "pendente") -> ok | F6: =IF(COUNTIFS(Forms!$G:$G, $A6, Forms!$H:$H, F$1) > 0, "ok", "pendente") -> pendente | G6: =IF(COUNTIFS(Forms!$G:$G, $A6, Forms!$H:$H, G$1) > 0, "ok", "pendente") -> pendente
A7: ECO RUN - PORTO ALEGRE - 28/06 | B7: =IF(COUNTIFS(Forms!$G:$G, $A7, Forms!$H:$H, B$1) > 0, "ok", "pendente") -> ok | C7: =IF(COUNTIFS(Forms!$G:$G, $A7, Forms!$H:$H, C$1) > 0, "ok", "pendente") -> pendente | D7: =IF(COUNTIFS(Forms!$G:$G, $A7, Forms!$H:$H, D$1) > 0, "ok", "pendente") -> pendente | E7: =IF(COUNTIFS(Forms!$G:$G, $A7, Forms!$H:$H, E$1) > 0, "ok", "pendente") -> ok | F7: =IF(COUNTIFS(Forms!$G:$G, $A7, Forms!$H:$H, F$1) > 0, "ok", "pendente") -> pendente | G7: =IF(COUNTIFS(Forms!$G:$G, $A7, Forms!$H:$H, G$1) > 0, "ok", "pendente") -> pendente
A8: CIRCUITO BANCO DO BRASIL - SALVADOR - 28/06 | B8: =IF(COUNTIFS(Forms!$G:$G, $A8, Forms!$H:$H, B$1) > 0, "ok", "pendente") -> pendente | C8: =IF(COUNTIFS(Forms!$G:$G, $A8, Forms!$H:$H, C$1) > 0, "ok", "pendente") -> pendente | D8: =IF(COUNTIFS(Forms!$G:$G, $A8, Forms!$H:$H, D$1) > 0, "ok", "pendente") -> pendente | E8: =IF(COUNTIFS(Forms!$G:$G, $A8, Forms!$H:$H, E$1) > 0, "ok", "pendente") -> pendente | F8: =IF(COUNTIFS(Forms!$G:$G, $A8, Forms!$H:$H, F$1) > 0, "ok", "pendente") -> pendente | G8: =IF(COUNTIFS(Forms!$G:$G, $A8, Forms!$H:$H, G$1) > 0, "ok", "pendente") -> pendente
A9: SÓ QUERO PEDALAR - NUBANK - SALVADOR - 28/06 | B9: =IF(COUNTIFS(Forms!$G:$G, $A9, Forms!$H:$H, B$1) > 0, "ok", "pendente") -> ok | C9: =IF(COUNTIFS(Forms!$G:$G, $A9, Forms!$H:$H, C$1) > 0, "ok", "pendente") -> pendente | D9: =IF(COUNTIFS(Forms!$G:$G, $A9, Forms!$H:$H, D$1) > 0, "ok", "pendente") -> pendente | E9: =IF(COUNTIFS(Forms!$G:$G, $A9, Forms!$H:$H, E$1) > 0, "ok", "pendente") -> pendente | F9: =IF(COUNTIFS(Forms!$G:$G, $A9, Forms!$H:$H, F$1) > 0, "ok", "pendente") -> pendente | G9: =IF(COUNTIFS(Forms!$G:$G, $A9, Forms!$H:$H, G$1) > 0, "ok", "pendente") -> pendente
A10: C.E. INVERNO - VITÓRIA - 28/06 | B10: =IF(COUNTIFS(Forms!$G:$G, $A10, Forms!$H:$H, B$1) > 0, "ok", "pendente") -> ok | C10: =IF(COUNTIFS(Forms!$G:$G, $A10, Forms!$H:$H, C$1) > 0, "ok", "pendente") -> pendente | D10: =IF(COUNTIFS(Forms!$G:$G, $A10, Forms!$H:$H, D$1) > 0, "ok", "pendente") -> pendente | E10: =IF(COUNTIFS(Forms!$G:$G, $A10, Forms!$H:$H, E$1) > 0, "ok", "pendente") -> ok | F10: =IF(COUNTIFS(Forms!$G:$G, $A10, Forms!$H:$H, F$1) > 0, "ok", "pendente") -> pendente | G10: =IF(COUNTIFS(Forms!$G:$G, $A10, Forms!$H:$H, G$1) > 0, "ok", "pendente") -> pendente
A11: LONGEVIDADE BRADESCO - CAMPINAS - 28/06 | B11: =IF(COUNTIFS(Forms!$G:$G, $A11, Forms!$H:$H, B$1) > 0, "ok", "pendente") -> pendente | C11: =IF(COUNTIFS(Forms!$G:$G, $A11, Forms!$H:$H, C$1) > 0, "ok", "pendente") -> pendente | D11: =IF(COUNTIFS(Forms!$G:$G, $A11, Forms!$H:$H, D$1) > 0, "ok", "pendente") -> ok | E11: =IF(COUNTIFS(Forms!$G:$G, $A11, Forms!$H:$H, E$1) > 0, "ok", "pendente") -> ok | F11: =IF(COUNTIFS(Forms!$G:$G, $A11, Forms!$H:$H, F$1) > 0, "ok", "pendente") -> pendente | G11: =IF(COUNTIFS(Forms!$G:$G, $A11, Forms!$H:$H, G$1) > 0, "ok", "pendente") -> ok

Sheet Night Maringá
B2: Evento | C2: NIGHT RUN - ETAPA 1 - MARINGÁ - 21/06
B3: 1 | G3: 2 | T3: CONFORMIDADE - RESPOSTAS ORIGINAIS
B4: Conformidade | G4: Performance | O4: PERFORMANCE - RESPOSTAS ORIGINAIS | T4: ÁREA DE CENOGRAFIA | X4: =C2 -> NIGHT RUN - ETAPA 1 - MARINGÁ - 21/06
B5: Item | C5: status | D5: Comentários | G5: Item | H5: Peso | I5: Nota | J5: Total | K5: Comentários | O5: Área | P5: Avaliador | Q5: Nota | R5: Comentários | T5: Item | U5: status | V5: Comentários
B6: Todos usaram EPI na arena? | C6: Sim | D6: =V6 | E6: =IF(C6="sim",25,0) -> 25 | G6: Carga na saída do galpão | H6: 3 | I6: 8 | J6: =I6*H6 -> 24 | O6: Cenografia | P6: {=_xlfn.TEXTJOIN(", ", TRUE, _xlfn._xlws.FILTER(Forms!$F:$F, (Forms!$G:$G=$C$2) * (Forms!$H:$H=O6), "Sem avaliador"))} -> Sem avaliador | Q6: {=IFERROR(AVERAGE(_xlfn._xlws.FILTER(Forms!$U:$U, (Forms!$G:$G=$C$2) * (Forms!$H:$H=O6))), 0)} -> 0 | R6: {=IFERROR(_xlfn.TEXTJOIN("; ", 1, _xlfn._xlws.FILTER(Forms!$V:$V, (Forms!$G:$G=$C$2) * (Forms!$H:$H=O6))), "")} | T6: Todos usaram EPI na arena? | U6: {=IFERROR(_xlfn.TEXTJOIN("; ", 1, _xlfn._xlws.FILTER(Forms!$W:$W, (Forms!$G:$G=$C$2) * (Forms!$H:$H="Cenografia"))), "")} | V6: {=IFERROR(IF(ROW(A1)>4, "", _xlfn.TEXTJOIN("; ", 1, _xlfn._xlws.FILTER(IF(ROW(A1)=1, Forms!$X:$X, IF(ROW(A1)=2, Forms!$Z:$Z, IF(ROW(A1)=3, Forms!$AB:$AB, Forms!$T:$T))), (Forms!$G:$G=$C$2) * (Forms!$H:$H=IF(ROW(A1)=4, $O$11, $O$6))))), "")} | Y6: =$Q$25 -> 0
B7: Estaiamento e Aterramento foram feitos de maneira correta? | C7: Sim | D7: =V7 | E7: =IF(C7="sim",25,0) -> 25 | G7: Qualidade da entrega | H7: 3 | I7: 8 | J7: =I7*H7 -> 24 | O7: Atendimento | P7: {=_xlfn.TEXTJOIN(", ", TRUE, _xlfn._xlws.FILTER(Forms!$F:$F, (Forms!$G:$G=$C$2) * (Forms!$H:$H=O7), "Sem avaliador"))} -> Agatha | Q7: {=IFERROR(AVERAGE(_xlfn._xlws.FILTER(Forms!$M:$M, (Forms!$G:$G=$C$2) * (Forms!$H:$H=O7))), 0)} -> 10 | R7: {=IFERROR(_xlfn.TEXTJOIN("; ", 1, _xlfn._xlws.FILTER(Forms!$N:$N, (Forms!$G:$G=$C$2) * (Forms!$H:$H=O7))), "")} -> Elogiado pelo cliente | T7: Estaiamento e Aterramento foram feitos de maneira correta? | U7: {=IFERROR(_xlfn.TEXTJOIN("; ", 1, _xlfn._xlws.FILTER(Forms!$Y:$Y, (Forms!$G:$G=$C$2) * (Forms!$H:$H="Cenografia"))), "")} | V7: {=IFERROR(IF(ROW(A2)>4, "", _xlfn.TEXTJOIN("; ", 1, _xlfn._xlws.FILTER(IF(ROW(A2)=1, Forms!$X:$X, IF(ROW(A2)=2, Forms!$Z:$Z, IF(ROW(A2)=3, Forms!$AB:$AB, Forms!$T:$T))), (Forms!$G:$G=$C$2) * (Forms!$H:$H=IF(ROW(A2)=4, $O$11, $O$6))))), "")} | Y7: =$Q$25 -> 0
B8: Conduta e comportamento foram adequados? | C8: Sim | D8: =V8 | E8: =IF(C8="sim",25,0) -> 25 | G8: Prazo de entrega | H8: 3 | I8: 8 | J8: =I8*H8 -> 24 | K8: Entregaram bem | O8: Ativação | P8: {=_xlfn.TEXTJOIN(", ", TRUE, _xlfn._xlws.FILTER(Forms!$F:$F, (Forms!$G:$G=$C$2) * (Forms!$H:$H=O8), "Sem avaliador"))} -> Sem avaliador | Q8: {=IFERROR(AVERAGE(_xlfn._xlws.FILTER(Forms!$O:$O, (Forms!$G:$G=$C$2) * (Forms!$H:$H=O8))), 0)} -> 0 | R8: {=IFERROR(_xlfn.TEXTJOIN("; ", 1, _xlfn._xlws.FILTER(Forms!$P:$P, (Forms!$G:$G=$C$2) * (Forms!$H:$H=O8))), "")} | T8: Conduta e comportamento foram adequados? | U8: {=IFERROR(_xlfn.TEXTJOIN("; ", 1, _xlfn._xlws.FILTER(Forms!$AA:$AA, (Forms!$G:$G=$C$2) * (Forms!$H:$H="Cenografia"))), "")} | V8: {=IFERROR(IF(ROW(#REF!)>4, "", _xlfn.TEXTJOIN("; ", 1, _xlfn._xlws.FILTER(IF(ROW(#REF!)=1, Forms!$X:$X, IF(ROW(#REF!)=2, Forms!$Z:$Z, IF(ROW(#REF!)=3, Forms!$AB:$AB, Forms!$T:$T))), (Forms!$G:$G=$C$2) * (Forms!$H:$H=IF(ROW(#REF!)=4, $O$11, $O$6))))), "")} | Y8: =$Q$25 -> 0
B9: Todos os equipamentos e ferramentas retornaram? | C9: resposta pendente | D9: =V9 | E9: =IF(C9="sim",25,0) -> 0 | G9: Logistica Reversa | H9: 0 | I9: =Q10 -> 8 | J9: =I9*H9 -> 0 | K9: caminhão não voltou | O9: Produção | P9: {=_xlfn.TEXTJOIN(", ", TRUE, _xlfn._xlws.FILTER(Forms!$F:$F, (Forms!$G:$G=$C$2) * (Forms!$H:$H=O9), "Sem avaliador"))} -> Lucas vicenzo da Silva Proença | Q9: {=IFERROR(AVERAGE(_xlfn._xlws.FILTER(Forms!$Q:$Q, (Forms!$G:$G=$C$2) * (Forms!$H:$H=O9))), 0)} -> 10 | R9: {=IFERROR(_xlfn.TEXTJOIN("; ", 1, _xlfn._xlws.FILTER(Forms!$R:$R, (Forms!$G:$G=$C$2) * (Forms!$H:$H=O9))), "")} -> Entregaram tudo muito bem. Sem problemas. | T9: Todos os equipamentos e ferramentas retornaram? | U9: {=IFERROR(_xlfn.TEXTJOIN("; ", 1, _xlfn._xlws.FILTER(Forms!$S:$S, (Forms!$G:$G=$C$2) * (Forms!$H:$H="Ferramentas e Case (Cenografia)"))), "")} | V9: {=IFERROR(_xlfn.TEXTJOIN("; ", 1, _xlfn._xlws.FILTER(Forms!$T:$T, (Forms!$G:$G=$C$2) * (Forms!$H:$H="Ferramentas e Case (Cenografia)"))), "")} | Y9: =$Q$25 -> 0
E10: =SUM(E6:E9) -> 75 | G10: Perda de material/estrutura | H10: 0 | I10: =Q11 -> 4 | J10: =I10*H10 -> 0 | O10: Logística | P10: {=_xlfn.TEXTJOIN(", ", TRUE, _xlfn._xlws.FILTER(Forms!$F:$F, (Forms!$G:$G=$C$2) * (Forms!$H:$H=O10), "Sem avaliador"))} -> Sandro Paiva | Q10: {=IFERROR(AVERAGE(_xlfn._xlws.FILTER(Forms!$K:$K, (Forms!$G:$G=$C$2) * (Forms!$H:$H=O10))), 0)} -> 8 | R10: {=IFERROR(_xlfn.TEXTJOIN("; ", 1, _xlfn._xlws.FILTER(Forms!$L:$L, (Forms!$G:$G=$C$2) * (Forms!$H:$H=O10))), "")} -> Carga voltou adequado. | T10: Houveram atrasos ou faltas? | U10: {=IFERROR(_xlfn.TEXTJOIN("; ", 1, _xlfn._xlws.FILTER(Forms!$AC:$AC, (Forms!$G:$G=$C$2) * (Forms!$H:$H="Cenografia"))), "")} | Y10: =$Q$25 -> 0
B11: Conformidade | D11: {=_xlfn.IFS(E10=100, "100%", E10=75, "-10 pontos", E10=50, "-20 pontos", E10=25, "-30 pontos", E10=0, "- 40 pontos")} -> -10 pontos | G11: Performance | I11: =SUM(J6:J10)/SUM(H6:H10)*10 -> 80 | O11: Logística | P11: {=_xlfn.TEXTJOIN(", ", TRUE, _xlfn._xlws.FILTER(Forms!$F:$F, (Forms!$G:$G=$C$2) * (Forms!$H:$H=O11), "Sem avaliador"))} -> Sandro Paiva | Q11: {=IFERROR(AVERAGE(_xlfn._xlws.FILTER(Forms!$I:$I, (Forms!$G:$G=$C$2) * (Forms!$H:$H=O11))), 0)} -> 4 | R11: {=IFERROR(_xlfn.TEXTJOIN("; ", 1, _xlfn._xlws.FILTER(Forms!$J:$J, (Forms!$G:$G=$C$2) * (Forms!$H:$H=O11))), "")} -> 01 carrinho plataforma quebrado, 02 geradores quebrados e estão faltando 03 cavaletes de trânsito. | T11: Desempenho para mérito? | U11: {=IFERROR(_xlfn.TEXTJOIN("; ", 1, _xlfn._xlws.FILTER(Forms!$AD:$AD, (Forms!$G:$G=$C$2) * (Forms!$H:$H="Cenografia"))), "")} | V11: {=IFERROR(_xlfn.TEXTJOIN("; ", 1, _xlfn._xlws.FILTER(Forms!$AE:$AE, (Forms!$G:$G=$C$2) * (Forms!$H:$H="Cenografia"))), "")} | Y11: =$Q$25 -> 0
B13: Pontuação final do Evento | F13: =I11+((E10-100)/2.5) -> 70

Sheet Vale São Luís
B2: Evento | C2: CIRCUITO DE CORRIDAS VALE - SÃO LUÍS - 21/06
B3: 1 | G3: 2 | T3: CONFORMIDADE - RESPOSTAS ORIGINAIS
B4: Conformidade | G4: Performance | O4: PERFORMANCE - RESPOSTAS ORIGINAIS | T4: ÁREA DE CENOGRAFIA | X4: =C2 -> CIRCUITO DE CORRIDAS VALE - SÃO LUÍS - 21/06
B5: Item | C5: status | D5: Comentários | G5: Item | H5: Peso | I5: Nota | J5: Total | K5: Comentários | O5: Área | P5: Avaliador | Q5: Nota | R5: Comentários | T5: Item | U5: status | V5: Comentários
B6: Todos usaram EPI na arena? | C6: Sim | D6: =V6 | E6: =IF(C6="sim",25,0) -> 25 | G6: Carga na saída do galpão | H6: 0 | I6: =Q6 -> 0 | J6: =I6*H6 -> 0 | K6: Sem nota ...foi a carreta que tombou...A carga saiu certinha de Vitória | O6: Cenografia | P6: {=_xlfn.TEXTJOIN(", ", TRUE, _xlfn._xlws.FILTER(Forms!$F:$F, (Forms!$G:$G=$C$2) * (Forms!$H:$H=O6), "Sem avaliador"))} -> FRED | Q6: {=IFERROR(AVERAGE(_xlfn._xlws.FILTER(Forms!$U:$U, (Forms!$G:$G=$C$2) * (Forms!$H:$H=O6))), 0)} -> 0 | R6: {=IFERROR(_xlfn.TEXTJOIN("; ", 1, _xlfn._xlws.FILTER(Forms!$V:$V, (Forms!$G:$G=$C$2) * (Forms!$H:$H=O6))), "")} -> Sem nota ...foi a carreta que tombou...A carga saiu certinha de Vitória | T6: Todos usaram EPI na arena? | U6: {=IFERROR(_xlfn.TEXTJOIN("; ", 1, _xlfn._xlws.FILTER(Forms!$W:$W, (Forms!$G:$G=$C$2) * (Forms!$H:$H="Cenografia"))), "")} -> Sim | V6: {=IFERROR(IF(ROW(A1)>4, "", _xlfn.TEXTJOIN("; ", 1, _xlfn._xlws.FILTER(IF(ROW(A1)=1, Forms!$X:$X, IF(ROW(A1)=2, Forms!$Z:$Z, IF(ROW(A1)=3, Forms!$AB:$AB, Forms!$T:$T))), (Forms!$G:$G=$C$2) * (Forms!$H:$H=IF(ROW(A1)=4, $O$11, $O$6))))), "")} | Y6: =$Q$25 -> 0
B7: Estaiamento e Aterramento foram feitos de maneira correta? | C7: Sim | D7: =V7 | E7: =IF(C7="sim",25,0) -> 25 | G7: Qualidade da entrega | H7: 3 | I7: 8 | J7: =I7*H7 -> 24 | O7: Atendimento | P7: {=_xlfn.TEXTJOIN(", ", TRUE, _xlfn._xlws.FILTER(Forms!$F:$F, (Forms!$G:$G=$C$2) * (Forms!$H:$H=O7), "Sem avaliador"))} -> Agatha | Q7: {=IFERROR(AVERAGE(_xlfn._xlws.FILTER(Forms!$M:$M, (Forms!$G:$G=$C$2) * (Forms!$H:$H=O7))), 0)} -> 10 | R7: {=IFERROR(_xlfn.TEXTJOIN("; ", 1, _xlfn._xlws.FILTER(Forms!$N:$N, (Forms!$G:$G=$C$2) * (Forms!$H:$H=O7))), "")} -> Elogiado pelo cliente | T7: Estaiamento e Aterramento foram feitos de maneira correta? | U7: {=IFERROR(_xlfn.TEXTJOIN("; ", 1, _xlfn._xlws.FILTER(Forms!$Y:$Y, (Forms!$G:$G=$C$2) * (Forms!$H:$H="Cenografia"))), "")} -> Sim | V7: {=IFERROR(IF(ROW(A2)>4, "", _xlfn.TEXTJOIN("; ", 1, _xlfn._xlws.FILTER(IF(ROW(A2)=1, Forms!$X:$X, IF(ROW(A2)=2, Forms!$Z:$Z, IF(ROW(A2)=3, Forms!$AB:$AB, Forms!$T:$T))), (Forms!$G:$G=$C$2) * (Forms!$H:$H=IF(ROW(A2)=4, $O$11, $O$6))))), "")} | Y7: =$Q$25 -> 0
B8: Conduta e comportamento foram adequados? | C8: Sim | D8: =V8 | E8: =IF(C8="sim",25,0) -> 25 | G8: Prazo de entrega | H8: 3 | I8: 9 | J8: =I8*H8 -> 27 | K8: A ENTREGA POR PARTE DA CENOGRAFIA FOI BOA | O8: Ativação | P8: {=_xlfn.TEXTJOIN(", ", TRUE, _xlfn._xlws.FILTER(Forms!$F:$F, (Forms!$G:$G=$C$2) * (Forms!$H:$H=O8), "Sem avaliador"))} -> Sem avaliador | Q8: {=IFERROR(AVERAGE(_xlfn._xlws.FILTER(Forms!$O:$O, (Forms!$G:$G=$C$2) * (Forms!$H:$H=O8))), 0)} -> 0 | R8: {=IFERROR(_xlfn.TEXTJOIN("; ", 1, _xlfn._xlws.FILTER(Forms!$P:$P, (Forms!$G:$G=$C$2) * (Forms!$H:$H=O8))), "")} | T8: Conduta e comportamento foram adequados? | U8: {=IFERROR(_xlfn.TEXTJOIN("; ", 1, _xlfn._xlws.FILTER(Forms!$AA:$AA, (Forms!$G:$G=$C$2) * (Forms!$H:$H="Cenografia"))), "")} -> Sim | V8: {=IFERROR(IF(ROW(#REF!)>4, "", _xlfn.TEXTJOIN("; ", 1, _xlfn._xlws.FILTER(IF(ROW(#REF!)=1, Forms!$X:$X, IF(ROW(#REF!)=2, Forms!$Z:$Z, IF(ROW(#REF!)=3, Forms!$AB:$AB, Forms!$T:$T))), (Forms!$G:$G=$C$2) * (Forms!$H:$H=IF(ROW(#REF!)=4, $O$11, $O$6))))), "")} | Y8: =$Q$25 -> 0
B9: Todos os equipamentos e ferramentas retornaram? | C9: resposta pendente | D9: =V9 | E9: =IF(C9="sim",25,0) -> 0 | G9: Logistica Reversa | H9: 0 | I9: =Q10 -> 0 | J9: =I9*H9 -> 0 | K9: não voltou ainda | O9: Produção | P9: {=_xlfn.TEXTJOIN(", ", TRUE, _xlfn._xlws.FILTER(Forms!$F:$F, (Forms!$G:$G=$C$2) * (Forms!$H:$H=O9), "Sem avaliador"))} -> RUBEM ISMAEL VASQUES | Q9: {=IFERROR(AVERAGE(_xlfn._xlws.FILTER(Forms!$Q:$Q, (Forms!$G:$G=$C$2) * (Forms!$H:$H=O9))), 0)} -> 5 | R9: {=IFERROR(_xlfn.TEXTJOIN("; ", 1, _xlfn._xlws.FILTER(Forms!$R:$R, (Forms!$G:$G=$C$2) * (Forms!$H:$H=O9))), "")} -> A ENTREGA POR PARTE DA CENOGRAFIA FOI MUITO BOA, COM TODOS OS PROBLEMAS QUE TIVEMOS COM A CARRETA E O MATERIAL DO JEITO QUE CHEGOU ELES MANDARAM MUITO BEM | T9: Todos os equipamentos e ferramentas retornaram? | U9: {=IFERROR(_xlfn.TEXTJOIN("; ", 1, _xlfn._xlws.FILTER(Forms!$S:$S, (Forms!$G:$G=$C$2) * (Forms!$H:$H="Ferramentas e Case (Cenografia)"))), "")} | V9: {=IFERROR(_xlfn.TEXTJOIN("; ", 1, _xlfn._xlws.FILTER(Forms!$T:$T, (Forms!$G:$G=$C$2) * (Forms!$H:$H="Ferramentas e Case (Cenografia)"))), "")} | Y9: =$Q$25 -> 0
E10: =SUM(E6:E9) -> 75 | G10: Perda de material/estrutura | H10: 3 | I10: 8 | J10: =I10*H10 -> 24 | O10: Logística | P10: {=_xlfn.TEXTJOIN(", ", TRUE, _xlfn._xlws.FILTER(Forms!$F:$F, (Forms!$G:$G=$C$2) * (Forms!$H:$H=O10), "Sem avaliador"))} -> Sem avaliador | Q10: {=IFERROR(AVERAGE(_xlfn._xlws.FILTER(Forms!$K:$K, (Forms!$G:$G=$C$2) * (Forms!$H:$H=O10))), 0)} -> 0 | R10: {=IFERROR(_xlfn.TEXTJOIN("; ", 1, _xlfn._xlws.FILTER(Forms!$L:$L, (Forms!$G:$G=$C$2) * (Forms!$H:$H=O10))), "")} | T10: Houveram atrasos ou faltas? | U10: {=IFERROR(_xlfn.TEXTJOIN("; ", 1, _xlfn._xlws.FILTER(Forms!$AC:$AC, (Forms!$G:$G=$C$2) * (Forms!$H:$H="Cenografia"))), "")} -> nao | Y10: =$Q$25 -> 0
B11: Conformidade | D11: {=_xlfn.IFS(E10=100, "100%", E10=75, "-10 pontos", E10=50, "-20 pontos", E10=25, "-30 pontos", E10=0, "- 40 pontos")} -> -10 pontos | G11: Performance | I11: =SUM(J6:J10)/SUM(H6:H10)*10 -> 83.333333 | O11: Logística | P11: {=_xlfn.TEXTJOIN(", ", TRUE, _xlfn._xlws.FILTER(Forms!$F:$F, (Forms!$G:$G=$C$2) * (Forms!$H:$H=O11), "Sem avaliador"))} -> Sem avaliador | Q11: {=IFERROR(AVERAGE(_xlfn._xlws.FILTER(Forms!$I:$I, (Forms!$G:$G=$C$2) * (Forms!$H:$H=O11))), 0)} -> 0 | R11: {=IFERROR(_xlfn.TEXTJOIN("; ", 1, _xlfn._xlws.FILTER(Forms!$J:$J, (Forms!$G:$G=$C$2) * (Forms!$H:$H=O11))), "")} | T11: Desempenho para mérito? | U11: {=IFERROR(_xlfn.TEXTJOIN("; ", 1, _xlfn._xlws.FILTER(Forms!$AD:$AD, (Forms!$G:$G=$C$2) * (Forms!$H:$H="Cenografia"))), "")} -> Sim, houve um grande destaque | V11: {=IFERROR(_xlfn.TEXTJOIN("; ", 1, _xlfn._xlws.FILTER(Forms!$AE:$AE, (Forms!$G:$G=$C$2) * (Forms!$H:$H="Cenografia"))), "")} -> Bruno Cordeiro - Cenotecnico.... reconstruiu variados tipos de peças que quebraram , ajudou em todos os setores, até bateu grade na madrugada. muito prestativo. | Y11: =$Q$25 -> 0
B13: Pontuação final do Evento | F13: =I11+((E10-100)/2.5) -> 73.333333

Sheet Trofeu BR
B2: Evento | C2: 35º TROFÉU BRASIL DE TRIATHLON - ETAPA 2 - 21/06
B3: 1 | G3: 2 | T3: CONFORMIDADE - RESPOSTAS ORIGINAIS
B4: Conformidade | G4: Performance | O4: PERFORMANCE - RESPOSTAS ORIGINAIS | T4: ÁREA DE CENOGRAFIA | X4: =C2 -> 35º TROFÉU BRASIL DE TRIATHLON - ETAPA 2 - 21/06
B5: Item | C5: status | D5: Comentários | G5: Item | H5: Peso | I5: Nota | J5: Total | K5: Comentários | O5: Área | P5: Avaliador | Q5: Nota | R5: Comentários | T5: Item | U5: status | V5: Comentários
B6: Todos usaram EPI na arena? | C6: Sim | D6: =V6 | E6: =IF(C6="sim",25,0) -> 25 | G6: Carga na saída do galpão | H6: 3 | I6: 8 | J6: =I6*H6 -> 24 | O6: Cenografia | P6: {=_xlfn.TEXTJOIN(", ", TRUE, _xlfn._xlws.FILTER(Forms!$F:$F, (Forms!$G:$G=$C$2) * (Forms!$H:$H=O6), "Sem avaliador"))} -> Sem avaliador | Q6: {=IFERROR(AVERAGE(_xlfn._xlws.FILTER(Forms!$U:$U, (Forms!$G:$G=$C$2) * (Forms!$H:$H=O6))), 0)} -> 0 | R6: {=IFERROR(_xlfn.TEXTJOIN("; ", 1, _xlfn._xlws.FILTER(Forms!$V:$V, (Forms!$G:$G=$C$2) * (Forms!$H:$H=O6))), "")} | T6: Todos usaram EPI na arena? | U6: {=IFERROR(_xlfn.TEXTJOIN("; ", 1, _xlfn._xlws.FILTER(Forms!$W:$W, (Forms!$G:$G=$C$2) * (Forms!$H:$H="Cenografia"))), "")} | V6: {=IFERROR(IF(ROW(A1)>4, "", _xlfn.TEXTJOIN("; ", 1, _xlfn._xlws.FILTER(IF(ROW(A1)=1, Forms!$X:$X, IF(ROW(A1)=2, Forms!$Z:$Z, IF(ROW(A1)=3, Forms!$AB:$AB, Forms!$T:$T))), (Forms!$G:$G=$C$2) * (Forms!$H:$H=IF(ROW(A1)=4, $O$11, $O$6))))), "")} | Y6: =$Q$25 -> 0
B7: Estaiamento e Aterramento foram feitos de maneira correta? | C7: Sim | D7: =V7 | E7: =IF(C7="sim",25,0) -> 25 | G7: Qualidade da entrega | H7: 3 | I7: 8 | J7: =I7*H7 -> 24 | O7: Atendimento | P7: {=_xlfn.TEXTJOIN(", ", TRUE, _xlfn._xlws.FILTER(Forms!$F:$F, (Forms!$G:$G=$C$2) * (Forms!$H:$H=O7), "Sem avaliador"))} -> Agatha | Q7: {=IFERROR(AVERAGE(_xlfn._xlws.FILTER(Forms!$M:$M, (Forms!$G:$G=$C$2) * (Forms!$H:$H=O7))), 0)} -> 10 | R7: {=IFERROR(_xlfn.TEXTJOIN("; ", 1, _xlfn._xlws.FILTER(Forms!$N:$N, (Forms!$G:$G=$C$2) * (Forms!$H:$H=O7))), "")} -> Elogiado pelo cliente | T7: Estaiamento e Aterramento foram feitos de maneira correta? | U7: {=IFERROR(_xlfn.TEXTJOIN("; ", 1, _xlfn._xlws.FILTER(Forms!$Y:$Y, (Forms!$G:$G=$C$2) * (Forms!$H:$H="Cenografia"))), "")} | V7: {=IFERROR(IF(ROW(A2)>4, "", _xlfn.TEXTJOIN("; ", 1, _xlfn._xlws.FILTER(IF(ROW(A2)=1, Forms!$X:$X, IF(ROW(A2)=2, Forms!$Z:$Z, IF(ROW(A2)=3, Forms!$AB:$AB, Forms!$T:$T))), (Forms!$G:$G=$C$2) * (Forms!$H:$H=IF(ROW(A2)=4, $O$11, $O$6))))), "")} | Y7: =$Q$25 -> 0
B8: Conduta e comportamento foram adequados? | C8: Sim | D8: =V8 | E8: =IF(C8="sim",25,0) -> 25 | G8: Prazo de entrega | H8: 3 | I8: 9 | J8: =I8*H8 -> 27 | O8: Ativação | P8: {=_xlfn.TEXTJOIN(", ", TRUE, _xlfn._xlws.FILTER(Forms!$F:$F, (Forms!$G:$G=$C$2) * (Forms!$H:$H=O8), "Sem avaliador"))} -> Sem avaliador | Q8: {=IFERROR(AVERAGE(_xlfn._xlws.FILTER(Forms!$O:$O, (Forms!$G:$G=$C$2) * (Forms!$H:$H=O8))), 0)} -> 0 | R8: {=IFERROR(_xlfn.TEXTJOIN("; ", 1, _xlfn._xlws.FILTER(Forms!$P:$P, (Forms!$G:$G=$C$2) * (Forms!$H:$H=O8))), "")} | T8: Conduta e comportamento foram adequados? | U8: {=IFERROR(_xlfn.TEXTJOIN("; ", 1, _xlfn._xlws.FILTER(Forms!$AA:$AA, (Forms!$G:$G=$C$2) * (Forms!$H:$H="Cenografia"))), "")} | V8: {=IFERROR(IF(ROW(#REF!)>4, "", _xlfn.TEXTJOIN("; ", 1, _xlfn._xlws.FILTER(IF(ROW(#REF!)=1, Forms!$X:$X, IF(ROW(#REF!)=2, Forms!$Z:$Z, IF(ROW(#REF!)=3, Forms!$AB:$AB, Forms!$T:$T))), (Forms!$G:$G=$C$2) * (Forms!$H:$H=IF(ROW(#REF!)=4, $O$11, $O$6))))), "")} | Y8: =$Q$25 -> 0
B9: Todos os equipamentos e ferramentas retornaram? | C9: resposta pendente | D9: =V9 | E9: =IF(C9="sim",25,0) -> 0 | G9: Logistica Reversa | H9: 3 | I9: 6 | J9: =I9*H9 -> 18 | O9: Produção | P9: {=_xlfn.TEXTJOIN(", ", TRUE, _xlfn._xlws.FILTER(Forms!$F:$F, (Forms!$G:$G=$C$2) * (Forms!$H:$H=O9), "Sem avaliador"))} -> Luciano do Nascimento | Q9: {=IFERROR(AVERAGE(_xlfn._xlws.FILTER(Forms!$Q:$Q, (Forms!$G:$G=$C$2) * (Forms!$H:$H=O9))), 0)} -> 10 | R9: {=IFERROR(_xlfn.TEXTJOIN("; ", 1, _xlfn._xlws.FILTER(Forms!$R:$R, (Forms!$G:$G=$C$2) * (Forms!$H:$H=O9))), "")} -> Vou dar 10 para a equipe que trabalhou porém eram 2 marceneiros e só foi 1 esse trabalhou por 2 | T9: Todos os equipamentos e ferramentas retornaram? | U9: {=IFERROR(_xlfn.TEXTJOIN("; ", 1, _xlfn._xlws.FILTER(Forms!$S:$S, (Forms!$G:$G=$C$2) * (Forms!$H:$H="Ferramentas e Case (Cenografia)"))), "")} | V9: {=IFERROR(_xlfn.TEXTJOIN("; ", 1, _xlfn._xlws.FILTER(Forms!$T:$T, (Forms!$G:$G=$C$2) * (Forms!$H:$H="Ferramentas e Case (Cenografia)"))), "")} | Y9: =$Q$25 -> 0
E10: =SUM(E6:E9) -> 75 | G10: Perda de material/estrutura | H10: 3 | I10: 8 | J10: =I10*H10 -> 24 | K10: 1 guarda corpo quebrado | O10: Logística | P10: {=_xlfn.TEXTJOIN(", ", TRUE, _xlfn._xlws.FILTER(Forms!$F:$F, (Forms!$G:$G=$C$2) * (Forms!$H:$H=O10), "Sem avaliador"))} -> Sem avaliador | Q10: {=IFERROR(AVERAGE(_xlfn._xlws.FILTER(Forms!$K:$K, (Forms!$G:$G=$C$2) * (Forms!$H:$H=O10))), 0)} -> 0 | R10: {=IFERROR(_xlfn.TEXTJOIN("; ", 1, _xlfn._xlws.FILTER(Forms!$L:$L, (Forms!$G:$G=$C$2) * (Forms!$H:$H=O10))), "")} | T10: Houveram atrasos ou faltas? | U10: {=IFERROR(_xlfn.TEXTJOIN("; ", 1, _xlfn._xlws.FILTER(Forms!$AC:$AC, (Forms!$G:$G=$C$2) * (Forms!$H:$H="Cenografia"))), "")} | Y10: =$Q$25 -> 0
B11: Conformidade | D11: {=_xlfn.IFS(E10=100, "100%", E10=75, "-10 pontos", E10=50, "-20 pontos", E10=25, "-30 pontos", E10=0, "- 40 pontos")} -> -10 pontos | G11: Performance | I11: =SUM(J6:J10)/SUM(H6:H10)*10 -> 78 | O11: Logística | P11: {=_xlfn.TEXTJOIN(", ", TRUE, _xlfn._xlws.FILTER(Forms!$F:$F, (Forms!$G:$G=$C$2) * (Forms!$H:$H=O11), "Sem avaliador"))} -> Sem avaliador | Q11: {=IFERROR(AVERAGE(_xlfn._xlws.FILTER(Forms!$I:$I, (Forms!$G:$G=$C$2) * (Forms!$H:$H=O11))), 0)} -> 0 | R11: {=IFERROR(_xlfn.TEXTJOIN("; ", 1, _xlfn._xlws.FILTER(Forms!$J:$J, (Forms!$G:$G=$C$2) * (Forms!$H:$H=O11))), "")} | T11: Desempenho para mérito? | U11: {=IFERROR(_xlfn.TEXTJOIN("; ", 1, _xlfn._xlws.FILTER(Forms!$AD:$AD, (Forms!$G:$G=$C$2) * (Forms!$H:$H="Cenografia"))), "")} | V11: {=IFERROR(_xlfn.TEXTJOIN("; ", 1, _xlfn._xlws.FILTER(Forms!$AE:$AE, (Forms!$G:$G=$C$2) * (Forms!$H:$H="Cenografia"))), "")} | Y11: =$Q$25 -> 0
B13: Pontuação final do Evento | F13: =I11+((E10-100)/2.5) -> 68

Sheet Inverno Manaus
B2: Evento | C2: CIRCUITO DE CORRIDAS VALE - SÃO LUÍS - 21/06
B3: 1 | G3: 2 | T3: CONFORMIDADE - RESPOSTAS ORIGINAIS
B4: Conformidade | G4: Performance | O4: PERFORMANCE - RESPOSTAS ORIGINAIS | T4: ÁREA DE CENOGRAFIA | X4: =C2 -> CIRCUITO DE CORRIDAS VALE - SÃO LUÍS - 21/06
B5: Item | C5: status | D5: Comentários | G5: Item | H5: Peso | I5: Nota | J5: Total | K5: Comentários | O5: Área | P5: Avaliador | Q5: Nota | R5: Comentários | T5: Item | U5: status | V5: Comentários
